Workbook

Sheet Source
A1: skip
A3: Hypothèses de quantités par archétypes
A5: Tirado, R.; Aublet, A.; Laurenceau, S.; Thorel, M.; Louërat, M.; Habert, G. Component-Based Model for Building Material Stock and Waste-Flow Characterization: A Case in the Île-de-France Region. Sustainability 2021, 13, 13159. https://doi.org/10.3390/su132313159
A6: Voir fichier « supplementary informations modif"
A8: P6 uniquement (2013 – 2022)
A9: Quantités par m²SDP | B9: unité | C9: Individual_housing | D9: Collective_housing | E9: Office | F9: Industrial | G9: Education
A10: IW: concrete and stone | B10: kg/m² | C10: 601.52407 | D10: 690.29249 | E10: 268.55117 | F10: 324.6078 | G10: 371.59859
A11: IW: bricks | B11: kg/m² | C11: 39.866793 | D11: 9.6896542 | E11: 2.1719789 | F11: 12.039116 | G11: 1.6634953
A12: IW: roof tiles | B12: kg/m² | C12: 25.464796 | D12: 0 | E12: 8.9268015 | F12: 5.8864609 | G12: 5.3887924
A13: IW: ceramics | B13: kg/m² | C13: 22.60265 | D13: 27.7518 | E13: 4.5610143 | F13: 7.2709807 | G13: 6.0808448
A14: NHW: gypsum plasterboards and planks | B14: kg/m² | C14: 28.989108 | D14: 24.281758 | E14: 10.983452 | F14: 11.254282 | G14: 11.922064
A15: NHW: insulation mineral wools | B15: kg/m² | C15: 0.38581376 | D15: 0.091765435 | E15: 0.27850918 | F15: 0.28379666 | G15: 0.33020828
A16: NHW: insulation other | B16: kg/m² | C16: 4.9446048 | D16: 0.62857817 | E16: 0 | F16: 0 | G16: 0
A17: NHW: metals ferrous | B17: kg/m² | C17: 0.99184099 | D17: 0.60374442 | E17: 0.30269179 | F17: 0.21299388 | G17: 0.29204973
A18: nhw metals non ferrous | B18: kg/m² | C18: 0 | D18: 0 | E18: 0.17500139 | F18: 0.67401834 | G18: 0.21630063
A19: NHW: windows | B19: kg/m² | C19: 6.9555552 | D19: 4.6959227 | E19: 2.7904912 | F19: 2.7556979 | G19: 3.3827942
A20: NHW: wood low adjuvanted | B20: kg/m² | C20: 20.870898 | D20: 7.2473262 | E20: 7.6764169 | F20: 5.9734924 | G20: 5.2397236
A21: Other NHW | B21: kg/m² | C21: 0.39363006 | D21: 0.28662867 | E21: 0.27761658 | F21: 0.27915854 | G21: 0.29237697
A22: gaz consumption | B22: kWh/m² | C22: 0 | D22: 0 | E22: =Source!$B$55*Source!$B$31 -> 3500 | F22: =Source!$B$57*Source!$B$31 -> 2800 | G22: =E22 -> 3500
A23: electricity consumption | B23: kWh/m² | C23: =$B$52*$B$31 -> 4700 | D23: =$B$53*$B$31 -> 6800 | E23: =$B$54*$B$31 -> 5350 | F23: =$B$56*$B$31 -> 3300 | G23: =E23 -> 5350
A24: oil consumption | B24: kWh/m² | C24: 0 | D24: 0 | E24: 0 | F24: =B31*B58 -> 950 | G24: 0
A25: coal consumption | B25: kWh/m² | C25: 0 | D25: 0 | E25: 0 | F25: =B59*B31 -> 1200 | G25: 0
A26: water consumption | B26: m3/m² | C26: =$B$48*$B$31/$B$49 -> 88.709677 | D26: =$B$48*$B$31/$B$49 -> 88.709677 | E26: =B50*B31 -> 17 | F26: =B51*B31 -> 0.016627358 | G26: =B50*B31 -> 17
A27: construction | B27: month/m² | C27: =$B$60/30 -> 0.05 | D27: =$B$60/30 -> 0.05 | E27: =$B$60/30 -> 0.05 | F27: =$B$60/30 -> 0.05 | G27: =$B$60/30 -> 0.05
A29: Hypothèses diverses
B30: valeur | C30: unité | D30: Commentaires
A31: Durée de vie de référence | B31: 50 | C31: ans | D31: Age moyen du parc ?
A32: Densité du béton | B32: 2500 | C32: kg/m³ | M32: Calculette simplifiée E+C- Chantier typo autres que maisons individuelles
A33: Densité surfacique fenêtre alu | B33: 50.7 | C33: kg/m² | D33: Valeur fiches ecoinvent | M33: A indiquer
A34: Densité surfacique fenêtre PVC | B34: 94.5 | C34: kg/m² | D34: Valeur fiches ecoinvent | M34: nb mois grue été | N34: 4 | O34: sur un an
A35: Densité surfacique fenêtre bois | B35: 80.2 | C35: kg/m² | D35: Valeur fiches ecoinvent | M35: nb mois grue hiver | N35: 4 | O35: sur un an
A36: Part fenêtre alu | B36: 0.51 | C36: - | D36: https://www.insee.fr/fr/statistiques/3587175 | M36: nb mois sans grue été | N36: 2 | O36: sur un an
A37: Part fenêtre PVC | B37: 0.32 | C37: - | D37: https://www.insee.fr/fr/statistiques/3587175 | M37: nb mois sans grue hiber | N37: 2 | O37: sur un an
A38: Part fenêtre bois | B38: =1-B36-B37 -> 0.17 | C38: - | D38: https://www.insee.fr/fr/statistiques/3587175 | M38: Quantité terres excavées | N38: 200 | O38: sur un an
A39: Densité volumique bois | B39: 600 | C39: kg/m³
A40: Conversion MJ – kWh | B40: 3.6 | C40: MJ/kWh | M40: resultats | N40: absolus | O40: par mois
A41: Densité énergétique gaz | B41: =36/B40 -> 10 | C41: kWh/m³ | D41: Net calorific value fiche ecoinvent market for natural gas, low pressure, FR | M41: Q cons elec | N41: =10400*(N34+N37)+N35*19500+N36*5200 -> 150800 | O41: =N41/12 -> 12566.667
A42: Densité eau | B42: 1000 | C42: kg/m³ | M42: Q terres | N42: =N38 -> 200 | O42: =N42/12 -> 16.666667
A43: Consommation chantier diesel MJ/mois | B43: 0.2 | C43: MJ/mois | M43: Q eau | N43: =(N34+N35)*60+40*(N36+N37) -> 640 | O43: =N43/12 -> 53.333333
A44: Consommation chantier elec kwh/mois | B44: =O41 -> 12566.667 | C44: kWh/mois | D44: cf calculette pour l’instant
...

Sheet Projects
A1: cutoff | B1: 20
A2: Database | B2: archetypes_metabo
A3: format | B3: Excel spreadsheet
A5: Activity | B5: programme_1991
A6: categories | B6: custom process
A7: code | B7: programme_1991
A8: comment | B8: un commentaire
A9: location | B9: FR
A10: production amount | B10: 1
A11: type | B11: process
A12: unit | B12: unit
A13: Exchanges
A14: name | B14: amount | C14: unit | D14: database | E14: categories | F14: location | G14: type | H14: uncertainty type | I14: loc | J14: scale | K14: shape | L14: minimum | M14: maximum
A15: programme_1991 | B15: 1 | C15: unit | D15: =$B$2 -> archetypes_metabo | E15: custom process | F15: FR | G15: production
A16: collective housing | B16: 520000 | C16: square meter | D16: =$B$2 -> archetypes_metabo | E16: custom process | F16: FR | G16: technosphere
A17: office building | B17: 1065000 | C17: square meter | D17: =$B$2 -> archetypes_metabo | E17: custom process | F17: FR | G17: technosphere
A18: education building | B18: 582000 | C18: square meter | D18: =$B$2 -> archetypes_metabo | E18: custom process | F18: FR | G18: technosphere
A19: roads | B19: 100000 | C19: square meter | D19: =$B$2 -> archetypes_metabo | E19: custom process | F19: FR | G19: technosphere
A20: vegetation | B20: 530000 | C20: square meter | D20: =$B$2 -> archetypes_metabo | E20: custom process | F20: FR | G20: technosphere
A22: Activity | B22: programme_1997
A23: categories | B23: custom process
A24: code | B24: programme_1997
A25: comment | B25: un commentaire
A26: location | B26: FR
A27: production amount | B27: 1
A28: type | B28: process
A29: unit | B29: unit
A30: Exchanges
A31: name | B31: amount | C31: unit | D31: database | E31: categories | F31: location | G31: type | H31: uncertainty type | I31: loc | J31: scale | K31: shape | L31: minimum | M31: maximum
A32: programme_1997 | B32: 1 | C32: unit | D32: =$B$2 -> archetypes_metabo | E32: custom process | F32: FR | G32: production
A33: collective housing | B33: 520000 | C33: square meter | D33: =$B$2 -> archetypes_metabo | E33: custom process | F33: FR | G33: technosphere
A34: office building | B34: 1050000 | C34: square meter | D34: =$B$2 -> archetypes_metabo | E34: custom process | F34: FR | G34: technosphere
A35: education building | B35: =(252+250+130+52)*1000 -> 684000 | C35: square meter | D35: =$B$2 -> archetypes_metabo | E35: custom process | F35: FR | G35: technosphere
A36: roads | B36: 100000 | C36: square meter | D36: =$B$2 -> archetypes_metabo | E36: custom process | F36: FR | G36: technosphere
A37: vegetation | B37: 80600 | C37: square meter | D37: =$B$2 -> archetypes_metabo | E37: custom process | F37: FR | G37: technosphere
A39: Activity | B39: programme_2002
A40: categories | B40: custom process
A41: code | B41: programme_2002
A42: comment | B42: un commentaire
A43: location | B43: FR
...

Sheet Archetypes
A1: skip
A2: Activity | B2: individual housing | C2: All columns past the first two for database and activity definitions are ignored in any case.
A3: categories | B3: custom_process
A4: code | B4: arch_individual_housing | C4: You can also use human-friendly identifiers like "acetic acid", just make sure they are unique
A5: comment | B5: archétype basé sur Tirado 2021 pour matières et BDNB pour consos
A6: location | B6: FR
A7: production amount | B7: 1
A8: type | B8: process
A9: unit | B9: square meter
A10: Exchanges
A11: name | B11: amount | C11: unit | D11: database | E11: categories | F11: location | G11: type | H11: uncertainty type | I11: loc | J11: scale | K11: shape | L11: minimum | M11: maximum
A12: individual housing | B12: 1 | C12: square meter | D12: =Projects!$B$2 -> archetypes_metabo | E12: custom_process | F12: FR | G12: production
A13: concrete and stone | B13: =Source!C10 -> 601.52407 | C13: kilogram | D13: =Projects!$B$2 -> archetypes_metabo | E13: custom_process | F13: FR | G13: technosphere | H13: =IF(B13=0,0,3) -> 3 | I13: =IF(B13>0,B13,"") -> 601.52407 | J13: =IF(I13="","",I13*Source!$B$77) -> 6015.2407 | L13: =IF(I13="","",0) -> 0
A14: bricks | B14: =Source!C11 -> 39.866793 | C14: kilogram | D14: =Projects!$B$2 -> archetypes_metabo | E14: custom_process | F14: FR | G14: technosphere | H14: =IF(B14=0,0,3) -> 3 | I14: =IF(B14>0,B14,"") -> 39.866793 | J14: =IF(I14="","",I14*Source!$B$77) -> 398.66793 | L14: =IF(I14="","",0) -> 0
A15: roof tiles | B15: =Source!C12 -> 25.464796 | C15: kilogram | D15: =Projects!$B$2 -> archetypes_metabo | E15: custom_process | F15: FR | G15: technosphere | H15: =IF(B15=0,0,3) -> 3 | I15: =IF(B15>0,B15,"") -> 25.464796 | J15: =IF(I15="","",I15*Source!$B$77) -> 254.64796 | L15: =IF(I15="","",0) -> 0
A16: ceramics | B16: =Source!C13 -> 22.60265 | C16: kilogram | D16: =Projects!$B$2 -> archetypes_metabo | E16: custom_process | F16: FR | G16: technosphere | H16: =IF(B16=0,0,3) -> 3 | I16: =IF(B16>0,B16,"") -> 22.60265 | J16: =IF(I16="","",I16*Source!$B$77) -> 226.0265 | L16: =IF(I16="","",0) -> 0
A17: gypsum | B17: =Source!C14 -> 28.989108 | C17: kilogram | D17: =Projects!$B$2 -> archetypes_metabo | E17: custom_process | F17: FR | G17: technosphere | H17: =IF(B17=0,0,3) -> 3 | I17: =IF(B17>0,B17,"") -> 28.989108 | J17: =IF(I17="","",I17*Source!$B$77) -> 289.89108 | L17: =IF(I17="","",0) -> 0
A18: mineral insulation | B18: =Source!C15 -> 0.38581376 | C18: kilogram | D18: =Projects!$B$2 -> archetypes_metabo | E18: custom_process | F18: FR | G18: technosphere | H18: =IF(B18=0,0,3) -> 3 | I18: =IF(B18>0,B18,"") -> 0.38581376 | J18: =IF(I18="","",I18*Source!$B$77) -> 3.8581376 | L18: =IF(I18="","",0) -> 0
A19: other insulation | B19: =Source!C16 -> 4.9446048 | C19: kilogram | D19: =Projects!$B$2 -> archetypes_metabo | E19: custom_process | F19: FR | G19: technosphere | H19: =IF(B19=0,0,3) -> 3 | I19: =IF(B19>0,B19,"") -> 4.9446048 | J19: =IF(I19="","",I19*Source!$B$77) -> 49.446048 | L19: =IF(I19="","",0) -> 0
A20: metals ferrous | B20: =Source!C17 -> 0.99184099 | C20: kilogram | D20: =Projects!$B$2 -> archetypes_metabo | E20: custom_process | F20: FR | G20: technosphere | H20: =IF(B20=0,0,3) -> 3 | I20: =IF(B20>0,B20,"") -> 0.99184099 | J20: =IF(I20="","",I20*Source!$B$77) -> 9.9184099 | L20: =IF(I20="","",0) -> 0
A21: metals non-ferrous | B21: =Source!C18 -> 0 | C21: kilogram | D21: =Projects!$B$2 -> archetypes_metabo | E21: custom_process | F21: FR | G21: technosphere | H21: =IF(B21=0,0,3) -> 0 | I21: =IF(B21>0,B21,"") | J21: =IF(I21="","",I21*Source!$B$77) | L21: =IF(I21="","",0)
A22: windows | B22: =Source!C19 -> 6.9555552 | C22: kilogram | D22: =Projects!$B$2 -> archetypes_metabo | E22: custom_process | F22: FR | G22: technosphere | H22: =IF(B22=0,0,3) -> 3 | I22: =IF(B22>0,B22,"") -> 6.9555552 | J22: =IF(I22="","",I22*Source!$B$77) -> 69.555552 | L22: =IF(I22="","",0) -> 0
A23: wood low adjuvanted | B23: =Source!C20 -> 20.870898 | C23: kilogram | D23: =Projects!$B$2 -> archetypes_metabo | E23: custom_process | F23: FR | G23: technosphere | H23: =IF(B23=0,0,3) -> 3 | I23: =IF(B23>0,B23,"") -> 20.870898 | J23: =IF(I23="","",I23*Source!$B$77) -> 208.70898 | L23: =IF(I23="","",0) -> 0
A24: other NHW | B24: =Source!C21 -> 0.39363006 | C24: kilogram | D24: =Projects!$B$2 -> archetypes_metabo | E24: custom_process | F24: FR | G24: technosphere | H24: =IF(B24=0,0,3) -> 3 | I24: =IF(B24>0,B24,"") -> 0.39363006 | J24: =IF(I24="","",I24*Source!$B$77) -> 3.9363006 | L24: =IF(I24="","",0) -> 0
... A26: electricity consumption | B26: =Source!C23 -> 4700 | C26: kwh | D26: =Projects!$B$2 -> archetypes_metabo | E26: custom_process | F26: FR | G26: technosphere | H26: =IF(B26=0,0,3) -> 3 | I26: =IF(B26>0,B26,"") -> 4700 | J26: =IF(I26="","",I26*Source!$B$77) -> 47000 | L26: =IF(I26="","",0) -> 0
A27: water consumption | B27: =Source!C26 -> 88.709677 | C27: cubic meter | D27: =Projects!$B$2 -> archetypes_metabo | E27: custom_process | F27: FR | G27: technosphere | H27: =IF(B27=0,0,3) -> 3 | I27: =IF(B27>0,B27,"") -> 88.709677 | J27: =IF(I27="","",I27*Source!$B$77) -> 887.09677 | L27: =IF(I27="","",0) -> 0
A28: construction | B28: =Source!C25 -> 0 | C28: month | D28: =Projects!$B$2 -> archetypes_metabo | E28: custom_process | F28: FR | G28: technosphere | H28: =IF(B28=0,0,3) -> 0 | I28: =IF(B28>0,B28,"") | J28: =IF(I28="","",I28*Source!$B$77) | L28: =IF(I28="","",0)
A30: Activity | B30: collective housing
A31: categories | B31: custom_process
A32: code | B32: arch_collective_housing
A33: comment | B33: archétype basé sur Tirado 2021 pour matières et BDNB pour consos
A34: location | B34: FR
A35: production amount | B35: 1
A36: type | B36: process
A37: unit | B37: square meter
A38: Exchanges
A39: name | B39: amount | C39: unit | D39: database | E39: categories | F39: location | G39: type | H39: uncertainty type | I39: loc | J39: scale | K39: shape | L39: minimum | M39: maximum
A40: collective housing | B40: 1 | C40: square meter | D40: =Projects!$B$2 -> archetypes_metabo | E40: custom_process | F40: FR | G40: production
A41: concrete and stone | B41: =Source!D10 -> 690.29249 | C41: kilogram | D41: =Projects!$B$2 -> archetypes_metabo | E41: custom_process | F41: FR | G41: technosphere | H41: =IF(B41=0,0,3) -> 3 | I41: =IF(B41>0,B41,"") -> 690.29249 | J41: =IF(I41="","",I41*Source!$B$77) -> 6902.9249 | L41: =IF(I41="","",0) -> 0
A42: bricks | B42: =Source!D11 -> 9.6896542 | C42: kilogram | D42: =Projects!$B$2 -> archetypes_metabo | E42: custom_process | F42: FR | G42: technosphere | H42: =IF(B42=0,0,3) -> 3 | I42: =IF(B42>0,B42,"") -> 9.6896542 | J42: =IF(I42="","",I42*Source!$B$77) -> 96.896542 | L42: =IF(I42="","",0) -> 0
...

Sheet Archetypes_wo_chantier
A1: Activity | B1: individual housing | C1: All columns past the first two for database and activity definitions are ignored in any case.
A2: categories | B2: custom_process
A3: code | B3: arch_individual_housing | C3: You can also use human-friendly identifiers like "acetic acid", just make sure they are unique
A4: comment | B4: archétype basé sur Tirado 2021 pour matières et BDNB pour consos
A5: location | B5: FR
A6: production amount | B6: 1
A7: type | B7: process
A8: unit | B8: square meter
A9: Exchanges
A10: name | B10: amount | C10: unit | D10: database | E10: categories | F10: location | G10: type | H10: uncertainty type | I10: loc | J10: scale | K10: shape | L10: minimum | M10: maximum
A11: individual housing | B11: 1 | C11: square meter | D11: =Projects!$B$2 -> archetypes_metabo | E11: custom_process | F11: FR | G11: production
A12: concrete and stone | B12: =Source!C10 -> 601.52407 | C12: kilogram | D12: =Projects!$B$2 -> archetypes_metabo | E12: custom_process | F12: FR | G12: technosphere | H12: =IF(B12=0,0,3) -> 3 | I12: =IF(B12>0,B12,"") -> 601.52407 | J12: =IF(I12="","",I12*Source!$B$77) -> 6015.2407
A13: bricks | B13: =Source!C11 -> 39.866793 | C13: kilogram | D13: =Projects!$B$2 -> archetypes_metabo | E13: custom_process | F13: FR | G13: technosphere | H13: =IF(B13=0,0,3) -> 3 | I13: =IF(B13>0,B13,"") -> 39.866793 | J13: =IF(I13="","",I13*Source!$B$77) -> 398.66793
A14: roof tiles | B14: =Source!C12 -> 25.464796 | C14: kilogram | D14: =Projects!$B$2 -> archetypes_metabo | E14: custom_process | F14: FR | G14: technosphere | H14: =IF(B14=0,0,3) -> 3 | I14: =IF(B14>0,B14,"") -> 25.464796 | J14: =IF(I14="","",I14*Source!$B$77) -> 254.64796
A15: ceramics | B15: =Source!C13 -> 22.60265 | C15: kilogram | D15: =Projects!$B$2 -> archetypes_metabo | E15: custom_process | F15: FR | G15: technosphere | H15: =IF(B15=0,0,3) -> 3 | I15: =IF(B15>0,B15,"") -> 22.60265 | J15: =IF(I15="","",I15*Source!$B$77) -> 226.0265
A16: gypsum | B16: =Source!C14 -> 28.989108 | C16: kilogram | D16: =Projects!$B$2 -> archetypes_metabo | E16: custom_process | F16: FR | G16: technosphere | H16: =IF(B16=0,0,3) -> 3 | I16: =IF(B16>0,B16,"") -> 28.989108 | J16: =IF(I16="","",I16*Source!$B$77) -> 289.89108
A17: mineral insulation | B17: =Source!C15 -> 0.38581376 | C17: kilogram | D17: =Projects!$B$2 -> archetypes_metabo | E17: custom_process | F17: FR | G17: technosphere | H17: =IF(B17=0,0,3) -> 3 | I17: =IF(B17>0,B17,"") -> 0.38581376 | J17: =IF(I17="","",I17*Source!$B$77) -> 3.8581376
A18: other insulation | B18: =Source!C16 -> 4.9446048 | C18: kilogram | D18: =Projects!$B$2 -> archetypes_metabo | E18: custom_process | F18: FR | G18: technosphere | H18: =IF(B18=0,0,3) -> 3 | I18: =IF(B18>0,B18,"") -> 4.9446048 | J18: =IF(I18="","",I18*Source!$B$77) -> 49.446048
A19: metals ferrous | B19: =Source!C17 -> 0.99184099 | C19: kilogram | D19: =Projects!$B$2 -> archetypes_metabo | E19: custom_process | F19: FR | G19: technosphere | H19: =IF(B19=0,0,3) -> 3 | I19: =IF(B19>0,B19,"") -> 0.99184099 | J19: =IF(I19="","",I19*Source!$B$77) -> 9.9184099
A20: metals non-ferrous | B20: =Source!C18 -> 0 | C20: kilogram | D20: =Projects!$B$2 -> archetypes_metabo | E20: custom_process | F20: FR | G20: technosphere | H20: =IF(B20=0,0,3) -> 0 | I20: =IF(B20>0,B20,"") | J20: =IF(I20="","",I20*Source!$B$77)
A21: windows | B21: =Source!C19 -> 6.9555552 | C21: kilogram | D21: =Projects!$B$2 -> archetypes_metabo | E21: custom_process | F21: FR | G21: technosphere | H21: =IF(B21=0,0,3) -> 3 | I21: =IF(B21>0,B21,"") -> 6.9555552 | J21: =IF(I21="","",I21*Source!$B$77) -> 69.555552
A22: wood low adjuvanted | B22: =Source!C20 -> 20.870898 | C22: kilogram | D22: =Projects!$B$2 -> archetypes_metabo | E22: custom_process | F22: FR | G22: technosphere | H22: =IF(B22=0,0,3) -> 3 | I22: =IF(B22>0,B22,"") -> 20.870898 | J22: =IF(I22="","",I22*Source!$B$77) -> 208.70898
A23: other NHW | B23: =Source!C21 -> 0.39363006 | C23: kilogram | D23: =Projects!$B$2 -> archetypes_metabo | E23: custom_process | F23: FR | G23: technosphere | H23: =IF(B23=0,0,3) -> 3 | I23: =IF(B23>0,B23,"") -> 0.39363006 | J23: =IF(I23="","",I23*Source!$B$77) -> 3.9363006
... A25: electricity consumption | B25: =Source!C23 -> 4700 | C25: kwh | D25: =Projects!$B$2 -> archetypes_metabo | E25: custom_process | F25: FR | G25: technosphere | H25: =IF(B25=0,0,3) -> 3 | I25: =IF(B25>0,B25,"") -> 4700 | J25: =IF(I25="","",I25*Source!$B$77) -> 47000
A26: water consumption | B26: =Source!C26 -> 88.709677 | C26: cubic meter | D26: =Projects!$B$2 -> archetypes_metabo | E26: custom_process | F26: FR | G26: technosphere | H26: =IF(B26=0,0,3) -> 3 | I26: =IF(B26>0,B26,"") -> 88.709677 | J26: =IF(I26="","",I26*Source!$B$77) -> 887.09677
A28: Activity | B28: collective housing
A29: categories | B29: custom_process
A30: code | B30: arch_collective_housing
A31: comment | B31: archétype basé sur Tirado 2021 pour matières et BDNB pour consos
A32: location | B32: FR
A33: production amount | B33: 1
A34: type | B34: process
A35: unit | B35: square meter
A36: Exchanges
A37: name | B37: amount | C37: unit | D37: database | E37: categories | F37: location | G37: type | H37: uncertainty type | I37: loc | J37: scale | K37: shape | L37: minimum | M37: maximum
A38: collective housing | B38: 1 | C38: square meter | D38: =Projects!$B$2 -> archetypes_metabo | E38: custom_process | F38: FR | G38: production
A39: concrete and stone | B39: =Source!D10 -> 690.29249 | C39: kilogram | D39: =Projects!$B$2 -> archetypes_metabo | E39: custom_process | F39: FR | G39: technosphere | H39: =IF(B39=0,0,3) -> 3 | I39: =IF(B39>0,B39,"") -> 690.29249 | J39: =IF(I39="","",I39*Source!$B$77) -> 6902.9249
A40: bricks | B40: =Source!D11 -> 9.6896542 | C40: kilogram | D40: =Projects!$B$2 -> archetypes_metabo | E40: custom_process | F40: FR | G40: technosphere | H40: =IF(B40=0,0,3) -> 3 | I40: =IF(B40>0,B40,"") -> 9.6896542 | J40: =IF(I40="","",I40*Source!$B$77) -> 96.896542
A41: roof tiles | B41: =Source!D12 -> 0 | C41: kilogram | D41: =Projects!$B$2 -> archetypes_metabo | E41: custom_process | F41: FR | G41: technosphere | H41: =IF(B41=0,0,3) -> 0 | I41: =IF(B41>0,B41,"") | J41: =IF(I41="","",I41*Source!$B$77)
A42: ceramics | B42: =Source!D13 -> 27.7518 | C42: kilogram | D42: =Projects!$B$2 -> archetypes_metabo | E42: custom_process | F42: FR | G42: technosphere | H42: =IF(B42=0,0,3) -> 3 | I42: =IF(B42>0,B42,"") -> 27.7518 | J42: =IF(I42="","",I42*Source!$B$77) -> 277.518
...

Sheet Material_categories
A1: Activity | B1: concrete and stone
A2: categories | B2: custom_process
A3: code | B3: concrete_and_stone
A4: comment | B4: archétype classification Tirado 2021
A5: location | B5: FR
A6: production amount | B6: 1
A7: type | B7: process
A8: unit | B8: kilogram
A9: dve | B9: 100
A10: Exchanges
A11: name | B11: amount | C11: unit | D11: database | E11: categories | F11: location | G11: type | H11: uncertainty type | I11: loc | J11: scale | K11: shape | L11: minimum | M11: maximum
A12: concrete and stone | B12: 1 | C12: kilogram | D12: =Projects!$B$2 -> archetypes_metabo | F12: FR | G12: production
A13: market for concrete, 35MPa | B13: =1/Source!B32 -> 0.0004 | C13: cubic meter | D13: ecoinvent-3.11-cutoff | F13: RoW | G13: technosphere
A14: market for waste concrete | B14: =-B12 -> -1 | C14: kilogram | D14: ecoinvent-3.11-cutoff | F14: Europe without Switzerland | G14: technosphere
A16: Activity | B16: bricks
A17: categories | B17: custom_process
A18: code | B18: bricks_code
A19: comment | B19: archétype classification Tirado 2021
A20: location | B20: FR
A21: production amount | B21: 1
A22: type | B22: process
A23: unit | B23: kilogram
A24: dve | B24: 100
A25: Exchanges
A26: name | B26: amount | C26: unit | D26: database | E26: categories | F26: location | G26: type | H26: uncertainty type | I26: loc | J26: scale | K26: shape | L26: minimum | M26: maximum
A27: bricks | B27: 1 | C27: kilogram | D27: =Projects!$B$2 -> archetypes_metabo | F27: FR | G27: production
A28: market for sand-lime brick | B28: =B21 -> 1 | C28: kilogram | D28: ecoinvent-3.11-cutoff | F28: GLO | G28: technosphere
A29: market for waste brick | B29: =-B28 -> -1 | C29: kilogram | D29: ecoinvent-3.11-cutoff | F29: Europe without Switzerland | G29: technosphere
A31: Activity | B31: roof tiles
A32: categories | B32: custom_process
A33: code | B33: roof_tiles
A34: comment | B34: archétype classification Tirado 2021
A35: location | B35: FR
A36: production amount | B36: 1
A37: type | B37: process
A38: unit | B38: kilogram
A39: dve | B39: 100
A40: Exchanges
A41: name | B41: amount | C41: unit | D41: database | E41: categories | F41: location | G41: type | H41: uncertainty type | I41: loc | J41: scale | K41: shape | L41: minimum | M41: maximum
A42: roof tiles | B42: 1 | C42: kilogram | D42: =Projects!$B$2 -> archetypes_metabo | F42: FR | G42: production
...

Sheet Consumptions
A1: Activity | B1: gaz consumption
A2: categories | B2: custom_process
A3: code | B3: gaz_consumption
A4: comment | B4: consos gaz ville FR
A5: location | B5: FR
A6: production amount | B6: 1
A7: type | B7: process
A8: unit | B8: kwh
A9: Exchanges
A10: name | B10: amount | C10: unit | D10: database | E10: categories | F10: location | G10: type | H10: uncertainty type | I10: loc | J10: scale | K10: shape | L10: minimum | M10: maximum
A11: gaz consumption | B11: 1 | C11: kwh | D11: =Projects!$B$2 -> archetypes_metabo | F11: FR | G11: production
A12: market for natural gas, low pressure | B12: =B6/Source!B41 -> 0.1 | C12: cubic meter | D12: ecoinvent-3.11-cutoff | F12: FR | G12: technosphere
A14: Activity | B14: electricity consumption
A15: categories | B15: custom_process
A16: code | B16: electricity_consumption
A17: comment | B17: consos élec FR
A18: location | B18: FR
A19: production amount | B19: 1
A20: type | B20: process
A21: unit | B21: kwh
A22: Exchanges
A23: name | B23: amount | C23: unit | D23: database | E23: categories | F23: location | G23: type | H23: uncertainty type | I23: loc | J23: scale | K23: shape | L23: minimum | M23: maximum
A24: electricity consumption | B24: 1 | C24: kwh | D24: =Projects!$B$2 -> archetypes_metabo | F24: FR | G24: production
A25: market for electricity, low voltage | B25: 1 | C25: kwh | D25: ecoinvent-3.11-cutoff | F25: FR | G25: technosphere
A27: Activity | B27: water consumption
A28: categories | B28: custom_process
A29: code | B29: water_consumption
A30: comment | B30: consos eau FR
A31: location | B31: FR
A32: production amount | B32: 1
A33: type | B33: process
A34: unit | B34: cubic meter
A35: Exchanges
A36: name | B36: amount | C36: unit | D36: database | E36: categories | F36: location | G36: type | H36: uncertainty type | I36: loc | J36: scale | K36: shape | L36: minimum | M36: maximum
A37: water consumption | B37: 1 | C37: cubic meter | D37: =Projects!$B$2 -> archetypes_metabo | F37: FR | G37: production
A38: market for tap water | B38: =B32*Source!B42 -> 1000 | C38: kilogram | D38: ecoinvent-3.11-cutoff | F38: Europe without Switzerland | G38: technosphere
A41: Activity | B41: oil consumption
A42: categories | B42: custom_process
A43: code | B43: oil_consumption
A44: comment | B44: consos pétrole FR
...

Sheet Construction
A1: Activity | B1: construction
A2: categories | B2: custom_process
A3: code | B3: construction_code
A4: comment | B4: procédé correspondant au temps de chantier
A5: location | B5: FR
A6: production amount | B6: 1
A7: type | B7: process
A8: unit | B8: month
A9: Exchanges
A10: name | B10: amount | C10: unit | D10: database | E10: categories | F10: location | G10: type | H10: uncertainty type | I10: loc | J10: scale | K10: shape | L10: minimum | M10: maximum
A11: construction | B11: 1 | C11: month | D11: =Projects!$B$2 -> archetypes_metabo | F11: FR | G11: production
A12: diesel, burned in building machine | B12: =Source!B43 -> 0.2 | C12: megajoule | D12: ecoinvent-3.11-cutoff | F12: GLO | G12: technosphere
A13: market for electricity, medium voltage | B13: =Source!B44 -> 12566.667 | C13: kwh | D13: ecoinvent-3.11-cutoff | F13: FR | G13: technosphere
A14: market group for transport, freight, lorry, diesel, unspecified | B14: =Source!B45*Source!B47/1000 -> 0.83333333 | C14: metric ton*km | D14: ecoinvent-3.11-cutoff | F14: GLO | G14: technosphere
A15: market for tap water | B15: 100 | C15: kilogram | D15: ecoinvent-3.11-cutoff | F15: Europe without Switzerland | G15: technosphere
